linaro@linaro-alip:~/slwebap_tinker/slwebap$ python manage.py makemigrations
Traceback (most recent call last):
  File "/home/linaro/slwebap_tinker/slwebap/manage.py", line 47, in <module>
    main()
  File "/home/linaro/slwebap_tinker/slwebap/manage.py", line 43, in main
    execute_from_command_line(sys.argv)
  File "/home/linaro/.pyenv/versions/3.10.4/lib/python3.10/site-packages/django/core/management/__init__.py", line 446, in execute_from_command_line
    utility.execute()
  File "/home/linaro/.pyenv/versions/3.10.4/lib/python3.10/site-packages/django/core/management/__init__.py", line 420, in execute
    django.setup()
  File "/home/linaro/.pyenv/versions/3.10.4/lib/python3.10/site-packages/django/__init__.py", line 24, in setup
    apps.populate(settings.INSTALLED_APPS)
  File "/home/linaro/.pyenv/versions/3.10.4/lib/python3.10/site-packages/django/apps/registry.py", line 124, in populate
    app_config.ready()
  File "/home/linaro/.pyenv/versions/3.10.4/lib/python3.10/site-packages/axes/apps.py", line 50, in ready
    from axes import checks, signals  # noqa
  File "/home/linaro/.pyenv/versions/3.10.4/lib/python3.10/site-packages/axes/signals.py", line 20, in <module>
    user_locked_out = Signal(providing_args=["request", "username", "ip_address"])
TypeError: Signal.__init__() got an unexpected keyword argument 'providing_args'
linaro@linaro-alip:~/slwebap_tinker/slwebap$ 
linaro@linaro-alip:~/slwebap_tinker/slwebap$ 
linaro@linaro-alip:~/slwebap_tinker/slwebap$ 
linaro@linaro-alip:~/slwebap_tinker/slwebap$ 
linaro@linaro-alip:~/slwebap_tinker/slwebap$ 
linaro@linaro-alip:~/slwebap_tinker/slwebap$ python3 manage.py runserver
INFO,2022-06-06 10:43:06,493,autoreload,8350,3069648912,Watching for file changes with StatReloader
Exception in thread django-main-thread:
Traceback (most recent call last):
  File "/home/linaro/.pyenv/versions/3.10.4/lib/python3.10/threading.py", line 1009, in _bootstrap_inner
    self.run()
  File "/home/linaro/.pyenv/versions/3.10.4/lib/python3.10/threading.py", line 946, in run
    self._target(*self._args, **self._kwargs)
  File "/home/linaro/.pyenv/versions/3.10.4/lib/python3.10/site-packages/django/utils/autoreload.py", line 64, in wrapper
    fn(*args, **kwargs)
  File "/home/linaro/.pyenv/versions/3.10.4/lib/python3.10/site-packages/django/core/management/commands/runserver.py", line 125, in inner_run
    autoreload.raise_last_exception()
  File "/home/linaro/.pyenv/versions/3.10.4/lib/python3.10/site-packages/django/utils/autoreload.py", line 87, in raise_last_exception
    raise _exception[1]
  File "/home/linaro/.pyenv/versions/3.10.4/lib/python3.10/site-packages/django/core/management/__init__.py", line 398, in execute
    autoreload.check_errors(django.setup)()
  File "/home/linaro/.pyenv/versions/3.10.4/lib/python3.10/site-packages/django/utils/autoreload.py", line 64, in wrapper
    fn(*args, **kwargs)
  File "/home/linaro/.pyenv/versions/3.10.4/lib/python3.10/site-packages/django/__init__.py", line 24, in setup
    apps.populate(settings.INSTALLED_APPS)
  File "/home/linaro/.pyenv/versions/3.10.4/lib/python3.10/site-packages/django/apps/registry.py", line 124, in populate
    app_config.ready()
  File "/home/linaro/.pyenv/versions/3.10.4/lib/python3.10/site-packages/axes/apps.py", line 50, in ready
    from axes import checks, signals  # noqa
  File "/home/linaro/.pyenv/versions/3.10.4/lib/python3.10/site-packages/axes/signals.py", line 20, in <module>
    user_locked_out = Signal(providing_args=["request", "username", "ip_address"])
TypeError: Signal.__init__() got an unexpected keyword argument 'providing_args'

